<?xml version="1.0"?>
<robot name="simple_arm">
  
  <!-- Base link -->
  <link name="base_link">
    <inertial>
      <mass value="1.0"/>
      <origin xyz="0 0 0" rpy="0 0 0"/>
      <inertia ixx="0.1" ixy="0" ixz="0" iyy="0.1" iyz="0" izz="0.1"/>
    </inertial>
    <visual>
      <geometry>
        <box size="0.2 0.2 0.1"/>
      </geometry>
    </visual>
  </link>
  
  <!-- First link -->
  <link name="link1">
    <inertial>
      <mass value="0.5"/>
      <origin xyz="0.25 0 0" rpy="0 0 0"/>
      <inertia ixx="0.05" ixy="0" ixz="0" iyy="0.05" iyz="0" izz="0.05"/>
    </inertial>
    <visual>
      <geometry>
        <cylinder radius="0.05" length="0.5"/>
      </geometry>
    </visual>
  </link>
  
  <!-- Second link -->
  <link name="link2">
    <inertial>
      <mass value="0.3"/>
      <origin xyz="0.15 0 0" rpy="0 0 0"/>
      <inertia ixx="0.03" ixy="0" ixz="0" iyy="0.03" iyz="0" izz="0.03"/>
    </inertial>
    <visual>
      <geometry>
        <cylinder radius="0.03" length="0.3"/>
      </geometry>
    </visual>
  </link>
  
  <!-- Joint 1: base to link1 -->
  <joint name="joint1" type="revolute">
    <parent link="base_link"/>
    <child link="link1"/>
    <origin xyz="0 0 0.1" rpy="0 0 0"/>
    <axis xyz="0 0 1"/>
    <limit lower="-3.14159" upper="3.14159" velocity="2.0" effort="10.0"/>
    <dynamics damping="0.1" friction="0.05"/>
  </joint>
  
  <!-- Joint 2: link1 to link2 -->
  <joint name="joint2" type="revolute">
    <parent link="link1"/>
    <child link="link2"/>
    <origin xyz="0.5 0 0" rpy="0 0 0"/>
    <axis xyz="0 0 1"/>
    <limit lower="-1.57" upper="1.57" velocity="2.0" effort="5.0"/>
    <dynamics damping="0.05" friction="0.02"/>
  </joint>
  
</robot>