<?xml version="1.0"?>
<mujoco model="simple_arm">
  
  <worldbody>
    
    <!-- Base body -->
    <body name="base" pos="0 0 0">
      <inertial mass="1.0" pos="0 0 0" diaginertia="0.1 0.1 0.1"/>
      <geom type="box" size="0.1 0.1 0.05"/>
      
      <!-- First link -->
      <body name="link1" pos="0 0 0.1">
        <inertial mass="0.5" pos="0.25 0 0" diaginertia="0.05 0.05 0.05"/>
        <joint name="joint1" type="hinge" axis="0 0 1" range="-3.14159 3.14159"/>
        <geom type="cylinder" size="0.05 0.25"/>
        
        <!-- Second link -->
        <body name="link2" pos="0.5 0 0">
          <inertial mass="0.3" pos="0.15 0 0" diaginertia="0.03 0.03 0.03"/>
          <joint name="joint2" type="hinge" axis="0 0 1" range="-1.57 1.57"/>
          <geom type="cylinder" size="0.03 0.15"/>
          
          <!-- End effector -->
          <body name="end_effector" pos="0.3 0 0">
            <inertial mass="0.1" pos="0 0 0" diaginertia="0.01 0.01 0.01"/>
            <geom type="sphere" size="0.02"/>
          </body>
          
        </body>
      </body>
    </body>
    
  </worldbody>
  
</mujoco>